Workbook

Sheet CR
A1: (€ million) | B1: 2021 | C1: 2022 | D1: 2023
A2: Net sales | B2: 37761 | C2: 42997 | D2: 43070
A3: Other revenues | B3: 1414 | C3: 2392 | D3: 3374
A4: Cost of sales | B4: -12255 | C4: -13695 | D4: -14236
A5: Gross profit | B5: 26920 | C5: 31694 | D5: 32208
A6: Research and development expenses | B6: -5692 | C6: -6706 | D6: -6728
A7: Selling and general expenses | B7: -9555 | C7: -10492 | D7: -10692 | F7: EBITDA | G7: 2021 | H7: 2022 | I7: 2023
A8: Other operating income | B8: 859 | C8: 1969 | D8: 1292 | G8: =SUM(B5:B9) -> 10727 | H8: =SUM(C5:C9) -> 13934 | I8: =SUM(D5:D9) -> 12564
A9: Other operating expenses | B9: -1805 | C9: -2531 | D9: -3516
A10: Amortization of intangible assets | B10: -1580 | C10: -2053 | D10: -2172
A11: Impairment of intangible assets | B11: -192 | C11: 454 | D11: -896
A12: Fair value remeasurement of contingent consideration | B12: -4 | C12: 27 | D12: -93
A13: Restructuring costs and similar items | B13: -820 | C13: -1336 | D13: -1.49
A14: Other gains and losses, and litigation | B14: -5 | C14: -370 | D14: -38
A15: Operating income | B15: 8126 | C15: 10656 | D15: 7875
A16: Financial expenses | B16: -368 | C16: -440 | D16: -1313
A17: Financial income | B17: 40 | C17: 206 | D17: 591
A18: Income before tax and investments accounted for using the equity method | B18: 7798 | C18: 10422 | D18: 7153
A19: Income tax expense | B19: -1558 | C19: -2006 | D19: -1602
A20: Share of profit/loss from investments accounted for usingthe equity method | B20: 39 | C20: 68 | D20: -115
... A27: Diluted earnings per share (€) | B27: 4.95 | C27: 6.66 | D27: 4.3

Sheet Bilan
A1: (€ million) | B1: 2021 | C1: 2022 | D1: 2023 | G1: Fond Propres | H1: 2021 | I1: 2022 | J1: 2023
A2: ASSETS | H2: =B23 -> 69031 | I2: =C23 -> 75152 | J2: =D23 -> 74353
A3: Property, plant and equipment | B3: 10028 | C3: 9869 | D3: 10160
A4: Right-of-use assets | B4: 1948 | C4: 1815 | D4: 1654
A5: Goodwill | B5: 48056 | C5: 49892 | D5: 49404
A6: Other intangible assets | B6: 21407 | C6: 21640 | D6: 24319
A7: Investments accounted for using the equity method | B7: 250 | C7: 677 | D7: 424
A8: Other non-current assets | B8: 3127 | C8: 3095 | D8: 3218
A9: Non-current income tax assets | B9: 175 | C9: 242 | D9: 188 | I9: Book value of equity | K9: 2021 | L9: 2022 | M9: 2023
A10: Deferred tax assets | B10: 4598 | C10: 5381 | D10: 6427 | K10: =B19-(B30+B37) -> 69031 | L10: =C19-(C30+C37) -> 75162 | M10: =D19-(D30+D37) -> 74366
A11: Non-current assets | B11: 89589 | C11: 92611 | D11: 95794
A12: Inventories | B12: 8715 | C12: 8.96 | D12: 9666
A13: Accounts receivable | B13: 7568 | C13: 8424 | D13: 8433
A14: Other current assets | B14: 3571 | C14: 3532 | D14: 3455
A15: Current income tax assets | B15: 612 | C15: 374 | D15: 391
A16: Cash and cash equivalents | B16: 10098 | C16: 12376 | D16: 8710
A17: Current assets | B17: 30564 | C17: 34026 | D17: 30655
A18: Assets held for sale or exchange | B18: 89 | C18: 85 | D18: 15
A19: Total Assets | B19: 120242 | C19: 126722 | D19: 126464
A20: LIABILITIES | J20: Net debt | L20: 2021 | M20: 2022 | N20: 2023
A21: Equity attributable to equity holders of Sanofi | B21: 68681 | C21: 74784 | D21: 74040 | L21: =B24+B36-B16 -> 10208 | M21: =C24+C36-C16 -> 6655 | N21: =D24+D36-D16 -> 7682
A22: Equity attributable to non-controlling interests | B22: 350 | C22: 368 | D22: 313
A23: Total equity | B23: 69031 | C23: 75152 | D23: 74353
A24: Long-term debt | B24: 17123 | C24: 14857 | D24: 14347
A25: Non-current lease liabilities | B25: 1839 | C25: 1904 | D25: 1755
A26: Non-current liabilities related to business combinations and to non-controlling interests | B26: 577 | C26: 674 | D26: 501
A27: Non-current provisions and other non-current liabilities | B27: 6721 | C27: 6341 | D27: 7602
A28: Non-current income tax liabilities | B28: 2039 | C28: 1979 | D28: 1842
A29: Deffered tax liabilities | B29: 1617 | C29: 1841 | D29: 1857
A30: Non-current liabilities | B30: 29916 | C30: 27596 | D30: 27904
A31: Accounts payable | B31: 6180 | C31: 6813 | D31: 7328
A32: Current liabilities related to business combinations and to non-controlling interests | B32: 137 | C32: 105 | D32: 208
A33: Current provisions and other current liabilities | B33: 11217 | C33: 12021 | D33: 13741
... A39: Total equity and liabilities | B39: 120242 | C39: 126722 | D39: 126464

Sheet Ratio
A1: (millions €) | B1: 2021 | C1: 2022 | D1: 2023 | H1: 2021 | I1: 2022 | J1: 2023
A2: Emprunts à long terme | B2: 17123 | C2: 14857 | D2: 14347 | G2: Ratio Dette / EBITDA | H2: =(B5)/B14 -> 1.8877599 | I2: =(C5)/C14 -> 1.3792163 | J2: =(D5)/D14 -> 1.3157434
A3: Emprunts à court terme et part à court terme de la dette à long terme | B3: 3183 | C3: 4174 | D3: 2045 | G3: Ratio Dette / Fonds propres | H3: =B5/B11 -> 0.29334647 | I3: =C5/C11 -> 0.25572174 | J3: =D5/D11 -> 0.22233131
A4: Instruments dérivés de taux et de change dédiés à la gestion de la dette financière | B4: -56 | C4: 187 | D4: 139
A5: Total dette financière | B5: =SUM(B2:B4) -> 20250 | C5: =SUM(C2:C4) -> 19218 | D5: =SUM(D2:D4) -> 16531
A6: Trésorerie et équivalents de trésorerie | B6: -10098 | C6: -12736 | D6: -8710
A7: Instruments dérivés de taux et de change dédiés à la gestion de la trésorerie et des équivalents de trésorerie | B7: -169 | C7: -45 | D7: -28
A8: Dette financière nette | B8: =SUM(B5:B7) -> 9983 | C8: =SUM(C5:C7) -> 6437 | D8: =SUM(D5:D7) -> 7793
A10: Fond Propres | B10: 2021 | C10: 2022 | D10: 2023
B11: 69031 | C11: 75152 | D11: 74353
A13: EBITDA | B13: 2021 | C13: 2022 | D13: 2023
B14: 10727 | C14: 13934 | D14: 12564

Sheet Liquidity
A1: Liquidity ratio | B1: Année
B2: 2021 | C2: 2022 | D2: 2023 | L2: Le current ratio mesure la capacité d'une entreprise à payer ses dettes à court terme avec ses actifs courants. En ce qui concerne Sanofi, ce ratio est en diminution chaque année. Cela signifie que Sanofi dispose de moins en moins d'actifs courants pour couvrir ses passifs courants. Bien que la baisse soit une tendance préoccupante , le current ratio reste supérieur à 1. Cela indique que Sanofi a encore suffisamment de ressources pour honorer ses obligations à court terme. Le quick ratio mesure la capacité d'une entreprise à payer ses dettes à court terme avec ses actifs les plus liquides. Après une légère amélioration en 2022, le ratio diminue en 2023 (0,70856411). Cela montre que Sanofi ne pourrait pas couvrir toutes ses dettes à court terme si elle devait exclure les stocks. De plus ce ratio étant inférieur à 1 signifie qu'il existe un risque potentiel si les passifs courants augmentaient soudainement. Le cash ratio, qui évalue la capacité de Sanofi à couvrir ses dettes à court terme uniquement avec la trésorerie et les équivalents de trésorerie, diminue fortement en 2023 (0,36). Cela signifie que Sanofi dispose de seulement 36 % de ses passifs courants en trésorerie disponible. Cette baisse peut indiquer une réduction des liquidités disponibles ou une gestion plus agressive des liquidités.
A3: Current ratio | B3: =Bilan!B17/Bilan!B37 -> 1.4352665 | C3: =Bilan!C17/Bilan!C37 -> 1.4198798 | D3: =Bilan!D17/Bilan!D37 -> 1.2670497
A4: Quick ratio | B4: =(Bilan!B16+Bilan!B13)/Bilan!B37 -> 0.82958441 | C4: =(Bilan!C16+Bilan!C13)/Bilan!C37 -> 0.86796862 | D4: =(Bilan!D16+Bilan!D13)/Bilan!D37 -> 0.70856411
A5: Cash ratio | B5: =Bilan!B16/Bilan!B37 -> 0.47419582 | C5: =Bilan!C16/Bilan!C37 -> 0.51644133 | D5: =Bilan!D16/Bilan!D37 -> 0.36000661

Sheet Cout dette
A1: (Millions €) | B1: 2021 | C1: 2022 | D1: 2023
A2: Cout dette financière | B2: 299 | C2: 376 | D2: 622
A3: Dette financière | B3: 20250 | C3: 19218 | D3: 16531 | F3: Cout Moyen Dette
A4: Cout d'emprunt | B4: =B2/B3 -> 0.014765432 | C4: =C2/C3 -> 0.019564991 | D4: =D2/D3 -> 0.037626278 | F4: =AVERAGE(B4:D5) -> 0.023985567
A6: Taux effectif d'imposition sur le résulat | B6: 0.2 | C6: 0.192 | D6: 0.224 | F6: Taux Moyen Imposition
F7: =AVERAGE(B6:D6) -> 0.20533333
B10: Cout dette nette moyen (Kd) | C10: =F4*(1-F7) -> 0.019060531

Sheet Structure dette
C1: 2021 | F1: 2022 | I1: 2023
A2: (en millions d’euros) | B2: Non courant | C2: Courant | D2: Total | E2: Non courant | F2: Courant | G2: Total | H2: Non courant | I2: Courant | J2: Total
A3: Emprunts obligataires | B3: 17118 | C3: 2828 | D3: 19946 | E3: 15044 | F3: 3817 | G3: 18861 | H3: 14416 | I3: 718 | J3: 15134
A4: Autres emprunts bancaires | B4: 21 | C4: 163 | D4: 184 | E4: 99 | F4: 187 | G4: 286 | H4: 130 | I4: 1118 | J4: 1248
A5: Autres emprunts | B5: 37 | C5: 3 | D5: 40 | F5: 6 | G5: 6 | I5: 6 | J5: 6
A6: Banques créditrices | C6: 189 | D6: 189 | F6: 168 | G6: 168 | I6: 203 | J6: 203
A7: Instruments dérivés de taux et de change dédiés à la gestion de la dette financière | C7: -45 | D7: -45 | F7: -48 | G7: -48 | I7: -18 | J7: -18
A8: Total dette financière valeur de remboursement | B8: 17176 | C8: 3138 | D8: 20314 | E8: 15143 | F8: 4130 | G8: 19273 | H8: 14546 | I8: 2027 | J8: 16573
A9: Cout amortissement | D9: -64 | G9: -55 | J9: -42
A10: Total dette financière valeur de bilan | D10: 20250 | G10: 19218 | J10: 16531
A13: % Répartition par types de financement | B13: 2021 | C13: 2022 | D13: 2023
A14: Emprunts obligataires | B14: =D3/$D$8 -> 0.98188441 | C14: =G3/$G$8 -> 0.97862294 | D14: =J3/$J$8 -> 0.91317203
A15: Autres emprunts bancaires | B15: =D4/$D$8 -> 0.0090577927 | C15: =G4/$G$8 -> 0.014839413 | D15: =J4/$J$8 -> 0.075303204
A16: Autres emprunts | B16: =D5/$D$8 -> 0.0019690854 | C16: =G5/$G$8 -> 0.00031131635 | D16: =J5/$J$8 -> 0.00036203463
A17: Autres | B17: =D6/$D$8 -> 0.0093039283 | C17: =G6/$G$8 -> 0.0087168578 | D17: =J6/$J$8 -> 0.012248838
A30: % Réparticipation par date de terme de financement | B30: 2021 | C30: 2022 | D30: 2023
A31: Court Terme (1 ans) | B31: =C8/D8 -> 0.15447475 | C31: =F8/G8 -> 0.21428942 | D31: =I8/J8 -> 0.12230737
A32: Long Terme (Supérieur à 1 an) | B32: =1-B31 -> 0.84552525 | C32: =1-C31 -> 0.78571058 | D32: =1-D31 -> 0.87769263

Sheet WACC
B2: Weighted Average Cost of Capital (WACC)
B3: Equity (Market Cap) | C3: =112.55*1000 -> 112550
B4: Debt | C4: ='Cout dette'!D3 -> 16531
B6: Cost of Debt | C6: ='Cout dette'!D4 -> 0.037626278
B7: Tax Rate | C7: 0.25
B8: D/(D+E) | C8: =C4/(C3+C4) -> 0.12806687
B9: After Tax Cost of Debt | C9: =C6*(1-C7) -> 0.028219708
B11: Risk Free Rate (German Gov 10 Year Bond) | C11: 0.023065
B12: Expected Market Return (3-year average annual return) | C12: 0.13104367
B13: Market Risk Premium | C13: =C12-C11 -> 0.10797867
B14: Beta (5Y Monthly) | C14: 0.44
B15: E/(D+E) | C15: =C3/(C3+C4) -> 0.87193313
B16: Cost of Equity | C16: =C11+C14*C13 -> 0.070575616
B18: WACC | C18: =C16*C15+C9*C8 -> 0.065151227

Sheet 3-year average annual return
A1: Date | B1: Adjusted Price | C1: Return | D1: Excess Return | F1: Mean | G1: SD | H1: 3-year Average Annual Return
A2: 44197 | B2: 66.1 | F2: =AVERAGE(C3:C38) -> 0.010314566 | G2: =_xlfn.STDEV.P(C3:C38) -> 0.059620499 | H2: =((1+F2)^12-1) -> 0.13104367
A3: 44228 | B3: 64.94 | C3: =B3/B2-1 -> -0.017549168 | D3: =C3-$F$2 -> -0.027863734
A4: 44256 | B4: 72.18 | C4: =B4/B3-1 -> 0.11148753 | D4: =C4-$F$2 -> 0.10117296 | F4: Sources: https://finance.yahoo.com/quote/SAN.PA/history/?frequency=1mo&period1=1577183868&period2=1735036662
A5: 44287 | B5: 74.77 | C5: =B5/B4-1 -> 0.035882516 | D5: =C5-$F$2 -> 0.02556795
A6: 44317 | B6: 74.51 | C6: =B6/B5-1 -> -0.0034773305 | D6: =C6-$F$2 -> -0.013791897
A7: 44348 | B7: 78.62 | C7: =B7/B6-1 -> 0.055160381 | D7: =C7-$F$2 -> 0.044845815
A8: 44378 | B8: 77.3 | C8: =B8/B7-1 -> -0.016789621 | D8: =C8-$F$2 -> -0.027104187
A9: 44409 | B9: 77.96 | C9: =B9/B8-1 -> 0.008538163 | D9: =C9-$F$2 -> -0.0017764033
A10: 44440 | B10: 73.92 | C10: =B10/B9-1 -> -0.051821447 | D10: =C10-$F$2 -> -0.062136013
A11: 44470 | B11: 76.9 | C11: =B11/B10-1 -> 0.040313853 | D11: =C11-$F$2 -> 0.029999286
A12: 44501 | B12: 74.61 | C12: =B12/B11-1 -> -0.029778934 | D12: =C12-$F$2 -> -0.0400935
A13: 44531 | B13: 78.81 | C13: =B13/B12-1 -> 0.056292722 | D13: =C13-$F$2 -> 0.045978156
A14: 44562 | B14: 82.52 | C14: =B14/B13-1 -> 0.047075244 | D14: =C14-$F$2 -> 0.036760678
A15: 44593 | B15: 83.17 | C15: =B15/B14-1 -> 0.0078768783 | D15: =C15-$F$2 -> -0.002437688
A16: 44621 | B16: 82.31 | C16: =B16/B15-1 -> -0.010340267 | D16: =C16-$F$2 -> -0.020654833
... A38: 45292 | B38: 89.64 | C38: =B38/B37-1 -> 0.040148526 | D38: =C38-$F$2 -> 0.02983396

Sheet ProfitRatios and OpReturns
D1: Profitability Ratios
C2: Year | D2: Gross Margin | E2: Operating Margin | F2: Net Profit Margin
C3: 2021 | D3: =CR!B5/CR!B2 -> 0.71290485 | E3: =CR!B15/CR!B2 -> 0.21519557 | F3: =CR!B21/CR!B2 -> 0.16628267
C4: 2022 | D4: =CR!C5/CR!C2 -> 0.73712119 | E4: =CR!C15/CR!C2 -> 0.24783124 | F4: =CR!C21/CR!C2 -> 0.19731609
C5: 2023 | D5: =CR!D5/CR!D2 -> 0.7478059 | E5: =CR!D15/CR!D2 -> 0.18284189 | F5: =CR!D21/CR!D2 -> 0.12621314
C9: Operating Returns
C10: Year | D10: ROA | E10: ROE
C11: 2021 | D11: =(CR!B21+CR!B16)/Bilan!K10 -> 0.085628196 | E11: =CR!B21/Bilan!K10 -> 0.090959134
C12: 2022 | D12: =(CR!C21+CR!C16)/Bilan!L10 -> 0.10702217 | E12: =CR!C21/Bilan!L10 -> 0.11287619
C13: 2023 | D13: =(CR!D21+CR!D16)/Bilan!M10 -> 0.055442003 | E13: =CR!D21/Bilan!M10 -> 0.073097921
D22: Book value of equity | F22: 2021 | G22: 2022 | H22: 2023

Sheet DCF & Sentivity
A1: (€ million) | B1: 2021 | C1: 2022 | D1: 2023 | T1: Sum of Discounted FCF | V1: =SUM(P31:V31) -> 22627.419
A2: Net sales | B2: 37761 | C2: 42997 | D2: 43070 | F2: I/ Les Prévisions sur 3 ans | H2: Année | I2: Net Sales | J2: Croissance annuelle | K2: Croissance Moyenne | N2: Growth Rate | O2: 0.02 | T2: Discounted Terminal value | V2: =(V31*(1+O2)/(O3-O2))*(1/(1+O3)^6) -> 48185.28
A3: Other revenues | B3: 1414 | C3: 2392 | D3: 3374 | H3: 2021 | I3: 37761 | N3: WACC | O3: =WACC!C18 -> 0.065151227
A4: Cost of sales | B4: 12255 | C4: 13695 | D4: 14236 | H4: 2022 | I4: 42997 | J4: =(I4-I3)/I3 -> 0.13866158 | T4: Enterprise Value (EV) | V4: =SUM(V1:V2) -> 70812.699
A5: Gross profit | B5: 26920 | C5: 31694 | D5: 32208 | H5: 2023 | I5: 43070 | J5: =(I5-I4)/I4 -> 0.0016977929 | K5: =(J4+J5)/2 -> 0.070179687 | T5: (Net debt) | V5: =Bilan!N21 -> 7682
A6: Research and development expenses | B6: 5692 | C6: 6706 | D6: 6728 | I6: Revenus Prévus | T6: Equity Value (EQ) | V6: =V4-V5 -> 63130.699
A7: Selling and general expenses | B7: 9555 | C7: 10492 | D7: 10692 | H7: 2024 | I7: =I5*(1+K5) -> 46092.639
A8: Other operating income | B8: 859 | C8: 1969 | D8: 1292 | H8: 2025 | I8: =I7*(1+K5) -> 49327.406 | M8: Année | N8: 2021 | O8: 2022 | P8: 2023 | Q8: 2024 | R8: 2025 | S8: 2026 | T8: 2027 | U8: 2028 | V8: 2029
A9: Other operating expenses | B9: -1805 | C9: -2531 | D9: -3516 | H9: 2026 | I9: =I8*(1+K5) -> 52789.188 | M9: Net Sales | N9: =B2 -> 37761 | O9: =C2 -> 42997 | P9: =D2 -> 43070 | Q9: =P9*(1+Q10) -> 46092.639 | R9: =Q9*(1+R10) -> 48864.823 | S9: =R9*(1+S10) -> 51215.954 | T9: =S9*(1+T10) -> 53187.359 | U9: =T9*(1+U10) -> 54825.189 | V9: =U9*(1+V10) -> 55921.693
A10: Amortization of intangible assets | B10: -1580 | C10: -2053 | D10: -2172 | M10: Revenue Growth | O10: =(O9-N9)/N9 -> 0.13866158 | P10: =(P9-O9)/O9 -> 0.0016977929 | Q10: =(O10+P10)/2 -> 0.070179687 | R10: =Q10-(Q10-V10)/5 -> 0.06014375 | S10: =R10-(R10-W10)/5 -> 0.048115 | T10: =S10-(S10-X10)/5 -> 0.038492 | U10: =T10-(T10-Y8)/5 -> 0.0307936 | V10: =O2 -> 0.02
A11: Impairment of intangible assets | B11: -192 | C11: 454 | D11: -896 | G11: 1) | H11: Récupération des données
A12: Fair value remeasurement of contingent consideration | B12: -4 | C12: 27 | D12: -93 | G12: 2) | H12: Le taux de croissance est calculé pour chaque année comme suit: | M12: EBITDA | N12: =CR!G8 -> 10727 | O12: =CR!H8 -> 13934 | P12: =CR!I8 -> 12564 | Q12: =Q$9*Q13 -> 13445.738 | R12: =R9*R13 -> 14254.415 | S12: =S9*S13 -> 14940.266 | T12: =T9*T13 -> 15515.347 | U12: =U9*U13 -> 15993.12 | V12: =V9*V13 -> 16312.982
A13: Restructuring costs and similar items | B13: -820 | C13: -1336 | D13: -1.49 | M13: EBITDA Margin | N13: =N12/N$9 -> 0.28407616 | O13: =O12/O$9 -> 0.32406912 | P13: =P12/P$9 -> 0.29171117 | Q13: =P13 -> 0.29171117 | R13: =Q13 -> 0.29171117 | S13: =R13 -> 0.29171117 | T13: =S13 -> 0.29171117 | U13: =T13 -> 0.29171117 | V13: =U13 -> 0.29171117
A14: Other gains and losses, and litigation | B14: -5 | C14: -370 | D14: -38 | H14: Croissance annuelle (%) = (Revenu actuel -Revenu précédent)/ Revenu précédent
A15: Operating income | B15: 8126 | C15: 10656 | D15: 7875 | M15: D&A | N15: =-CR!B10-CR!B11 -> 1772 | O15: =-CR!C10-CR!C11 -> 1599 | P15: =-CR!D10-CR!D11 -> 3068 | Q15: =Q$9*Q16 -> 2386.8035 | R15: =R$9*R16 -> 2530.3548 | S15: =S$9*S16 -> 2652.1028 | T15: =T$9*T16 -> 2754.1875 | U15: =U$9*U16 -> 2838.9989 | V15: =V$9*V16 -> 2895.7789
A16: Financial expenses | B16: -368 | C16: -440 | D16: -1313 | G16: 3) | H16: Calcul de la croissance moyenne | M16: In % of revenue | N16: =N15/N$9 -> 0.046926723 | O16: =O15/O$9 -> 0.037188641 | P16: =P15/P$9 -> 0.071232877 | Q16: =AVERAGE(N16:P16) -> 0.051782747 | R16: =Q16 -> 0.051782747 | S16: =R16 -> 0.051782747 | T16: =S16 -> 0.051782747 | U16: =T16 -> 0.051782747 | V16: =U16 -> 0.051782747
A17: Financial income | B17: 40 | C17: 206 | D17: 591 | H17: Pour estimer la croissance future, nous utilisons la moyenne des taux historiques
A18: Income before tax and investments accounted for using the equity method | B18: 7798 | C18: 10422 | D18: 7153 | M18: EBIT | N18: =B15 -> 8126 | O18: =C15 -> 10656 | P18: =D15 -> 7875 | Q18: =Q$9*Q19 -> 9923.2643 | R18: =R$9*R19 -> 10520.087 | S18: =S$9*S19 -> 11026.261 | T18: =T$9*T19 -> 11450.683 | U18: =U$9*U19 -> 11803.291 | V18: =V$9*V19 -> 12039.357 | X18: projected revenue * EBIT margin
A19: Income tax expense | B19: -1558 | C19: -2006 | D19: -1602 | H19: Croissance moyenne (%) = (Croissance 2022 + Croissance 2023)/2 | M19: EBIT Margin | N19: =N18/N$9 -> 0.21519557 | O19: =O18/O$9 -> 0.24783124 | P19: =P18/P$9 -> 0.18284189 | Q19: =AVERAGE(N19:P19) -> 0.21528957 | R19: =Q19 -> 0.21528957 | S19: =R19 -> 0.21528957 | T19: =S19 -> 0.21528957 | U19: =T19 -> 0.21528957 | V19: =U19 -> 0.21528957
A20: Share of profit/loss from investments accounted for usingthe equity method | B20: 39 | C20: 68 | D20: -115 | H20: Cette moyenne est utilisée comme hypothèse réaliste pour les projections.
A21: Net income | B21: 6279 | C21: 8484 | D21: 5436 | M21: Corporate tax (IS) | N21: =-CR!B19 -> 1558 | O21: =-CR!C19 -> 2006 | P21: =-CR!D19 -> 1602 | Q21: =Q18*Q22 -> 2480.8161 | R21: =R18*R22 -> 2630.0217 | S21: =S18*S22 -> 2756.5652 | T21: =T18*T22 -> 2862.6709 | U21: =U18*U22 -> 2950.8228 | V21: =V18*V22 -> 3009.8393 | X21: EBIT * Tax Rate
A22: Net income attributable to non-controlling interests | B22: 56 | C22: 113 | D22: 36 | G22: 4) | H22: Projection des revenus futurs | M22: Corporate tax rate | N22: 0.25 | O22: =N22 -> 0.25 | P22: =O22 -> 0.25 | Q22: =P22 -> 0.25 | R22: =Q22 -> 0.25 | S22: =R22 -> 0.25 | T22: =S22 -> 0.25 | U22: =T22 -> 0.25 | V22: =U22 -> 0.25
A23: Net income attributable to equity holders of Sanofi | B23: 6223 | C23: 8371 | D23: 5400 | H23: Les revenus futurs sont calculés en appliquant la croissance moyenne à chaque année. La formule est :
A24: Average number of shares outstanding (million) | B24: 1252.5 | C24: 1251.9 | D24: 1251.7 | M24: Investment | N24: =Bilan!B3 -> 10028 | O24: =Bilan!C3 -> 9869 | P24: =Bilan!D3 -> 10160 | Q24: =Q$9*Q25 -> 11231.051 | R24: =R$9*R25 -> 11906.528 | S24: =S$9*S25 -> 12479.411 | T24: =T$9*T25 -> 12959.768 | U24: =U$9*U25 -> 13358.846 | V24: =V$9*V25 -> 13626.023
A25: Average number of shares after dilution (million) | B25: 1257.9 | C25: 1256.9 | D25: 1256.4 | H25: Revenu futur = Revenu précédent×(1+Croissance moyenne) | M25: % of revenue | N25: =N24/N$9 -> 0.265565 | O25: =O24/O$9 -> 0.22952764 | P25: =P24/P$9 -> 0.23589505 | Q25: =AVERAGE(N25:P25) -> 0.24366257 | R25: =Q25 -> 0.24366257 | S25: =R25 -> 0.24366257 | T25: =S25 -> 0.24366257 | U25: =T25 -> 0.24366257 | V25: =U25 -> 0.24366257
A26: Basic earnings per share (€) | B26: 4.97 | C26: 6.69 | D26: 4.31
A27: Diluted earnings per share (€) | B27: 4.95 | C27: 6.66 | D27: 4.3 | M27: (WCR variation) | O27: =O34-N34 -> 793 | P27: =P34-O34 -> -3601 | Q27: =Q34-P34 -> 3210.662 | R27: =R34-Q34 -> 581.69002 | S27: =S34-R34 -> 493.34003 | T27: =T34-S34 -> 413.66167 | U27: =U34-T34 -> 343.66747 | V27: =V34-U34 -> 230.08042
F28: II/ Appliquer une croissance perpétuelle de 2 %
M29: Free Cash Flow | N29: =N18+N15-N24+N27+N21 -> 1428 | O29: =O18+O15-O24+O27+O21 -> 5185 | P29: =P18+P15-P24+P27+P21 -> -1216 | Q29: =Q18+Q15-Q24+Q27+Q21 -> 6770.4952 | R29: =R18+R15-R24+R27+R21 -> 4355.6249 | S29: =S18+S15-S24+S27+S21 -> 4448.8578 | T29: =T18+T15-T24+T27+T21 -> 4521.4352 | U29: =U18+U15-U24+U27+U21 -> 4577.9342 | V29: =V18+V15-V24+V27+V21 -> 4549.0325
G30: 1) | H30: Prenons le revenu estimé pour la dernière année des prévisions (dans notre cas, 2026 : 52789 M€).
G31: 2) | H31: Appliquons la croissance perpétuelle | M31: Discounted Free cash flow | P31: =P29/(1+$O$3)^(P8-2023) -> -1216 | Q31: =Q29/(1+$O$3)^(Q8-2023) -> 6356.3699 | R31: =R29/(1+$O$3)^(R8-2023) -> 3839.0868 | S31: =S29/(1+$O$3)^(S8-2023) -> 3681.4144 | T31: =T29/(1+$O$3)^(T8-2023) -> 3512.6205 | U31: =U29/(1+$O$3)^(U8-2023) -> 3338.9751 | V31: =V29/(1+$O$3)^(V8-2023) -> 3114.9523
H32: Utilisons la formule suivante pour calculer les revenus pour chaque année après 2026 : | M32: Discount factor | P32: =1/(1+$O$3)^(P8-2023) -> 1 | Q32: =1/(1+$O$3)^(Q8-2023) -> 0.93883382 | R32: =1/(1+$O$3)^(R8-2023) -> 0.88140895 | S32: =1/(1+$O$3)^(S8-2023) -> 0.82749653 | T32: =1/(1+$O$3)^(T8-2023) -> 0.77688174 | U32: =1/(1+$O$3)^(U8-2023) -> 0.72936285 | V32: =1/(1+$O$3)^(V8-2023) -> 0.68475052
H34: Revenu futur = Revenu précédent×(1+Croissance moyenne) | M34: WCR | N34: =Bilan!B17-Bilan!B37 -> 9269 | O34: =Bilan!C17-Bilan!C37 -> 10062 | P34: =Bilan!D17-Bilan!D37 -> 6461 | Q34: =Q9*Q35 -> 9671.662 | R34: =R9*R35 -> 10253.352 | S34: =S9*S35 -> 10746.692 | T34: =T9*T35 -> 11160.354 | U34: =U9*U35 -> 11504.021 | V34: =V9*V35 -> 11734.102
H35: Année | I35: Revenus Prévus | M35: % of revenue | N35: =N34/N9 -> 0.2454649 | O35: =O34/O9 -> 0.23401633 | P35: =P34/P9 -> 0.15001161 | Q35: =AVERAGE(N35:P35) -> 0.20983094 | R35: =Q35 -> 0.20983094 | S35: =R35 -> 0.20983094 | T35: =S35 -> 0.20983094 | U35: =T35 -> 0.20983094 | V35: =U35 -> 0.20983094
H36: 2026 | I36: 52789.188
H37: 2027 | I37: =I36*(1+$J$47) -> 53844.972
H38: 2028 | I38: =I37*(1+$J$47) -> 54921.871 | J38: VP | K38: =(I39*(1+$J$47))/($J$48-$J$47) -> 1265540.7 | L38: Terminal Value
H39: 2029 | I39: =I38*(1+$J$47) -> 56020.309
G41: 3) | H41: Calcul de la valeur perpétuelle
H42: La valeur perpétuelle est une estimation de la somme des revenus futurs actualisés après la période de prévisions (au-delà de 2026). Elle est calculée à l'aide de la formule suivante :
...

Sheet Feuil1
B2: Year | C2: 2021 A | D2: 2022 A | E2: 2023 A | F2: 2024 E | G2: 2025 E | H2: 2026 E | I2: 2027 E
B3: Net Sales | C3: 37761 | D3: 42997 | E3: 43070 | F3: 45774 | G3: 48648 | H3: 51703 | I3: 52737

Sheet Feuil2
